Workbook

Sheet 절압지도서
B1: 작 업 지 도 서 ( Work Sheet)
B3: 절 단 및 압 착 (Cut and Crimp) | M3: ㈜세림전자 (SerimElectronics)
M4: 양식No | N4: SLQD-250406
B5: 제품(PRODUCT) | C5: 얼음정수기 | E5: PJT | H5: RWP90H | M5: CODE | N5: DA96-01767C
B6: 개정 내용 (Revised content) | C6: NO | D6: 일 자 (Date) | E6: 내 용 (Content) | J6: 작성 (DESIGN) | K6: 검토 (CHECK) | L6: 승인 (APPROV) | M6: 비 고 (Bignoran)
C7: 1 | E7: 신규제정 | J7: 오민상 | L7: 김준범
C8: 2 | D8: 45931 | E8: 제빙기, 디스펜서 JOINT 전선 길이 단축 | J8: 오민상 | L8: 김준범
C9: 3 | D9: 45932 | E9: 제빙기, 디스펜서 STEP VALVE JOINT 전선 길이 변경 | J9: 오민상 | L9: 김준범
C10: 4 | D10: 45957 | E10: 하우징 사양, 전선 길이 변경, 68번 전선 추가 | J10: 오민상 | L10: 김준범
C11: 5 | D11: 45973 | E11: 54,55번전선 삭제, 52번 전선 핀맵 위치 변경 | J11: 오민상 | L11: 김준범
C12: 6 | D12: 45988 | E12: 제빙기 커넥터 사양 변경, 전선 길이, 정형 변경 | J12: 오민상 | L12: 김준범
C13: 7 | D13: 46043 | E13: 커넥터 변경(연호 --> KET), 전선 길이 변경, PVC 튜브 추가 | J13: 오민상 | L13: 김준범
C14: 8 | D14: 46090 | E14: 제빙기, 디스펜서 조인트 길이 단축 | J14: 오민상 | L14: 김준범
B15: 품 질 POINT (Quality POINT) | C15: 심선절단 (A core wire cutting) - 절연피복 STRIP시 심선에 흠 또는 그로인한 심선의 끊어짐이 없도록 할 것. (In case of insulation STRIP, make sure that the core is not damaged or broken.) 압착상태 (pressed condition) - 심선압착부 내측에 유지류 또는 기타 이물질이 없을 것. (Core apchakppu inner will not be fat and oils or other debris.) - 압착시 심선 압착부의 이음매에 심선의 일부가빠져 나오지 말 것. (Do not remove any part of the heart from the seam of the heart's compression section when) - 절연 피복의 일부가 심선 압착부에 들어가지 말 것. (Do not allow any part of the insulation to enter the core compression section.) - 압착부 절연피복은 절연피복 압착부에 고정될 것. (The insulation of the compression part shall be fixed to the insulation compression part.) 외 관 (The external appearance) - 사용상 문제가 없을 것. (No problem in use.)
B24: 측정 주기 (Measurement cycle) | C24: 초, 중, 종물 | E24: 측정 값 (Measured value) | H24: 탈피 길이,인장력 (Strip Length, tensile strength) | M24: 단 자 (Terminal)
B25: 품 명 (Product name) | C25: WIRE SPEC (mm) | H25: Wire Strip Length (mm) | L25: Tensile strength (kgf)
H26: A | J26: B | M26: A | N26: B | S26: Strip Length | U26: 이원화 자재
C27: NO | D27: 규 격 | E27: 색상 | F27: 길이 | G27: 원수 | H27: 길이 | I27: 방법 | J27: 길이 | K27: 방법 | O27: START | Q27: END | S27: A | T27: B | U27: A | V27: B
B28: 1767C-1 | C28: 1 | D28: 1007#24/A | E28: RED | F28: =10 + (90+20+40+50+40+90+60) +10 -> 410 | G28: 1 | H28: =IF(RIGHT(M28,5)="JOINT",IF(MID(D28,3,6)="1007#2","15","17"),IF(RIGHT(M28,6)="SPLICE",8,IF(AND(S28="",NOT(F28="")),#REF!,S28))) -> 2.5 | I28: =IF(M28="", "", IF(OR(M28="반탈피", ISNUMBER(SEARCH("JOINT", M28))), "반", "완")) -> 완 | J28: =IF(RIGHT(N28,5)="JOINT",IF(MID(D28,3,6)="1007#2","15","17"),IF(RIGHT(N28,6)="SPLICE",8,IF(AND(T28="",NOT(F28="")),#REF!,T28))) -> 1.9 | K28: =IF(N28="", "", IF(OR(N28="반탈피", ISNUMBER(SEARCH("JOINT", N28))), "반", "완")) -> 완 | M28: ST731509-3T | N28: ST731454-3SS | O28: 2 | P28: CN40 #1 | Q28: 7 | R28: MAIN PBA JOINT #9 | S28: =IFERROR(VLOOKUP(M28,'DATA(STRIP LENGTH)'!A:C,3,0),"") -> 2.5 | T28: =IFERROR(VLOOKUP(N28,'DATA(STRIP LENGTH)'!A:C,3,0),"") -> 1.9 | U28: =IFERROR(VLOOKUP(M28,이원화!A:B,2,0),"") -> WB20L-61209 | V28: =IFERROR(VLOOKUP(N28,이원화!A:B,2,0),"") -> YST025L3 | W28: =IF(C28>0,IF(B28=0,W27,B28),"") -> 1767C-1
C29: 2 | D29: 1007#24/A | E29: RED | F29: =10 + (90+20+40+50+40+90+60) +10 -> 410 | G29: 1 | H29: =IF(RIGHT(M29,5)="JOINT",IF(MID(D29,3,6)="1007#2","15","17"),IF(RIGHT(M29,6)="SPLICE",8,IF(AND(S29="",NOT(F29="")),#REF!,S29))) -> 2.5 | I29: =IF(M29="", "", IF(OR(M29="반탈피", ISNUMBER(SEARCH("JOINT", M29))), "반", "완")) -> 완 | J29: =IF(RIGHT(N29,5)="JOINT",IF(MID(D29,3,6)="1007#2","15","17"),IF(RIGHT(N29,6)="SPLICE",8,IF(AND(T29="",NOT(F29="")),#REF!,T29))) -> 1.9 | K29: =IF(N29="", "", IF(OR(N29="반탈피", ISNUMBER(SEARCH("JOINT", N29))), "반", "완")) -> 완 | M29: ST731509-3T | N29: ST731454-3SS | P29: CN40 #3 | R29: MAIN PBA JOINT #10 | S29: =IFERROR(VLOOKUP(M29,'DATA(STRIP LENGTH)'!A:C,3,0),"") -> 2.5 | T29: =IFERROR(VLOOKUP(N29,'DATA(STRIP LENGTH)'!A:C,3,0),"") -> 1.9 | U29: =IFERROR(VLOOKUP(M29,이원화!A:B,2,0),"") -> WB20L-61209 | V29: =IFERROR(VLOOKUP(N29,이원화!A:B,2,0),"") -> YST025L3 | W29: =IF(C29>0,IF(B29=0,W28,B29),"") -> 1767C-1
C30: 63 | D30: 1007#24/A | E30: BLK | F30: =10 + (90+20+40+50+40+90+60) +10 -> 410 | G30: 1 | H30: =IF(RIGHT(M30,5)="JOINT",IF(MID(D30,3,6)="1007#2","15","17"),IF(RIGHT(M30,6)="SPLICE",8,IF(AND(S30="",NOT(F30="")),#REF!,S30))) -> 2.5 | I30: =IF(M30="", "", IF(OR(M30="반탈피", ISNUMBER(SEARCH("JOINT", M30))), "반", "완")) -> 완 | J30: =IF(RIGHT(N30,5)="JOINT",IF(MID(D30,3,6)="1007#2","15","17"),IF(RIGHT(N30,6)="SPLICE",8,IF(AND(T30="",NOT(F30="")),#REF!,T30))) -> 1.9 | K30: =IF(N30="", "", IF(OR(N30="반탈피", ISNUMBER(SEARCH("JOINT", N30))), "반", "완")) -> 완 | M30: ST731509-3T | N30: ST731454-3SS | P30: CN40 #5 | R30: MAIN PBA JOINT #7 | S30: =IFERROR(VLOOKUP(M30,'DATA(STRIP LENGTH)'!A:C,3,0),"") -> 2.5 | T30: =IFERROR(VLOOKUP(N30,'DATA(STRIP LENGTH)'!A:C,3,0),"") -> 1.9 | U30: =IFERROR(VLOOKUP(M30,이원화!A:B,2,0),"") -> WB20L-61209 | V30: =IFERROR(VLOOKUP(N30,이원화!A:B,2,0),"") -> YST025L3 | W30: =IF(C30>0,IF(B30=0,W43,B30),"") -> #REF!
C31: 64 | D31: 1007#24/A | E31: BLK | F31: =10 + (90+20+40+50+40+90+60) +10 -> 410 | G31: 1 | H31: =IF(RIGHT(M31,5)="JOINT",IF(MID(D31,3,6)="1007#2","15","17"),IF(RIGHT(M31,6)="SPLICE",8,IF(AND(S31="",NOT(F31="")),#REF!,S31))) -> 2.5 | I31: =IF(M31="", "", IF(OR(M31="반탈피", ISNUMBER(SEARCH("JOINT", M31))), "반", "완")) -> 완 | J31: =IF(RIGHT(N31,5)="JOINT",IF(MID(D31,3,6)="1007#2","15","17"),IF(RIGHT(N31,6)="SPLICE",8,IF(AND(T31="",NOT(F31="")),#REF!,T31))) -> 1.9 | K31: =IF(N31="", "", IF(OR(N31="반탈피", ISNUMBER(SEARCH("JOINT", N31))), "반", "완")) -> 완 | M31: ST731509-3T | N31: ST731454-3SS | P31: CN40 #7 | R31: MAIN PBA JOINT #8 | S31: =IFERROR(VLOOKUP(M31,'DATA(STRIP LENGTH)'!A:C,3,0),"") -> 2.5 | T31: =IFERROR(VLOOKUP(N31,'DATA(STRIP LENGTH)'!A:C,3,0),"") -> 1.9 | U31: =IFERROR(VLOOKUP(M31,이원화!A:B,2,0),"") -> WB20L-61209 | V31: =IFERROR(VLOOKUP(N31,이원화!A:B,2,0),"") -> YST025L3 | W31: =IF(C31>0,IF(B31=0,W30,B31),"") -> #REF!
C32: 3 | D32: 2468#26 2C (BLK/WHT) | E32: BLK | F32: =10 + (90+40+100) +10 -> 250 | G32: 1 | H32: =IF(RIGHT(M32,5)="JOINT",IF(MID(D32,3,6)="1007#2","15","17"),IF(RIGHT(M32,6)="SPLICE",8,IF(AND(S32="",NOT(F32="")),#REF!,S32))) -> 2.5 | I32: =IF(M32="", "", IF(OR(M32="반탈피", ISNUMBER(SEARCH("JOINT", M32))), "반", "완")) -> 완 | J32: =IF(RIGHT(N32,5)="JOINT",IF(MID(D32,3,6)="1007#2","15","17"),IF(RIGHT(N32,6)="SPLICE",8,IF(AND(T32="",NOT(F32="")),#REF!,T32))) -> 3 | K32: =IF(N32="", "", IF(OR(N32="반탈피", ISNUMBER(SEARCH("JOINT", N32))), "반", "완")) -> 완 | M32: ST731509-3T | N32: ST741461-3T | P32: CN40 #6 | Q32: 5 | R32: STEP VALVE JOINT #11 | S32: =IFERROR(VLOOKUP(M32,'DATA(STRIP LENGTH)'!A:C,3,0),"") -> 2.5 | T32: =IFERROR(VLOOKUP(N32,'DATA(STRIP LENGTH)'!A:C,3,0),"") -> 3 | U32: =IFERROR(VLOOKUP(M32,이원화!A:B,2,0),"") -> WB20L-61209 | V32: =IFERROR(VLOOKUP(N32,이원화!A:B,2,0),"") -> 25045TP | W32: =IF(C32>0,IF(B32=0,W29,B32),"") -> 1767C-1
C33: 4 | E33: WHT | G33: 1 | H33: =IF(RIGHT(M33,5)="JOINT",IF(MID(D33,3,6)="1007#2","15","17"),IF(RIGHT(M33,6)="SPLICE",8,IF(AND(S33="",NOT(F33="")),#REF!,S33))) -> 2.5 | I33: =IF(M33="", "", IF(OR(M33="반탈피", ISNUMBER(SEARCH("JOINT", M33))), "반", "완")) -> 완 | J33: =IF(RIGHT(N33,5)="JOINT",IF(MID(D33,3,6)="1007#2","15","17"),IF(RIGHT(N33,6)="SPLICE",8,IF(AND(T33="",NOT(F33="")),#REF!,T33))) -> 3 | K33: =IF(N33="", "", IF(OR(N33="반탈피", ISNUMBER(SEARCH("JOINT", N33))), "반", "완")) -> 완 | M33: ST731509-3T | N33: ST741461-3T | P33: CN40 #8 | R33: STEP VALVE JOINT #12 | S33: =IFERROR(VLOOKUP(M33,'DATA(STRIP LENGTH)'!A:C,3,0),"") -> 2.5 | T33: =IFERROR(VLOOKUP(N33,'DATA(STRIP LENGTH)'!A:C,3,0),"") -> 3 | U33: =IFERROR(VLOOKUP(M33,이원화!A:B,2,0),"") -> WB20L-61209 | V33: =IFERROR(VLOOKUP(N33,이원화!A:B,2,0),"") -> 25045TP | W33: =IF(C33>0,IF(B33=0,W32,B33),"") -> 1767C-1
C34: 5 | D34: 1007#26/A | E34: BLU | F34: =10 + (90+20+40+50+40+90+75) +10 -> 425 | G34: 1 | H34: =IF(RIGHT(M34,5)="JOINT",IF(MID(D34,3,6)="1007#2","15","17"),IF(RIGHT(M34,6)="SPLICE",8,IF(AND(S34="",NOT(F34="")),#REF!,S34))) -> 2.5 | I34: =IF(M34="", "", IF(OR(M34="반탈피", ISNUMBER(SEARCH("JOINT", M34))), "반", "완")) -> 완 | J34: =IF(RIGHT(N34,5)="JOINT",IF(MID(D34,3,6)="1007#2","15","17"),IF(RIGHT(N34,6)="SPLICE",8,IF(AND(T34="",NOT(F34="")),#REF!,T34))) -> 1.9 | K34: =IF(N34="", "", IF(OR(N34="반탈피", ISNUMBER(SEARCH("JOINT", N34))), "반", "완")) -> 완 | M34: ST731509-3T | N34: ST731454-3SS | P34: CN40 #18 | Q34: 8 | R34: MAIN PBA JOINT 2 #5 | S34: =IFERROR(VLOOKUP(M34,'DATA(STRIP LENGTH)'!A:C,3,0),"") -> 2.5 | T34: =IFERROR(VLOOKUP(N34,'DATA(STRIP LENGTH)'!A:C,3,0),"") -> 1.9 | U34: =IFERROR(VLOOKUP(M34,이원화!A:B,2,0),"") -> WB20L-61209 | V34: =IFERROR(VLOOKUP(N34,이원화!A:B,2,0),"") -> YST025L3 | W34: =IF(C34>0,IF(B34=0,W33,B34),"") -> 1767C-1
C35: 6 | D35: 1007#26/A | E35: BLK | F35: =10 + (90+20+40+50+40+90+75) +10 -> 425 | G35: 1 | H35: =IF(RIGHT(M35,5)="JOINT",IF(MID(D35,3,6)="1007#2","15","17"),IF(RIGHT(M35,6)="SPLICE",8,IF(AND(S35="",NOT(F35="")),#REF!,S35))) -> 2.5 | I35: =IF(M35="", "", IF(OR(M35="반탈피", ISNUMBER(SEARCH("JOINT", M35))), "반", "완")) -> 완 | J35: =IF(RIGHT(N35,5)="JOINT",IF(MID(D35,3,6)="1007#2","15","17"),IF(RIGHT(N35,6)="SPLICE",8,IF(AND(T35="",NOT(F35="")),#REF!,T35))) -> 1.9 | K35: =IF(N35="", "", IF(OR(N35="반탈피", ISNUMBER(SEARCH("JOINT", N35))), "반", "완")) -> 완 | M35: ST731509-3T | N35: ST731454-3SS | P35: CN40 #20 | R35: MAIN PBA JOINT 2 #7 | S35: =IFERROR(VLOOKUP(M35,'DATA(STRIP LENGTH)'!A:C,3,0),"") -> 2.5 | T35: =IFERROR(VLOOKUP(N35,'DATA(STRIP LENGTH)'!A:C,3,0),"") -> 1.9 | U35: =IFERROR(VLOOKUP(M35,이원화!A:B,2,0),"") -> WB20L-61209 | V35: =IFERROR(VLOOKUP(N35,이원화!A:B,2,0),"") -> YST025L3 | W35: =IF(C35>0,IF(B35=0,W34,B35),"") -> 1767C-1
C36: 7 | D36: 1007#26/A | E36: RED | F36: =10 + (90+20+40+50+40+90+75) +10 -> 425 | G36: 1 | H36: =IF(RIGHT(M36,5)="JOINT",IF(MID(D36,3,6)="1007#2","15","17"),IF(RIGHT(M36,6)="SPLICE",8,IF(AND(S36="",NOT(F36="")),#REF!,S36))) -> 2.5 | I36: =IF(M36="", "", IF(OR(M36="반탈피", ISNUMBER(SEARCH("JOINT", M36))), "반", "완")) -> 완 | J36: =IF(RIGHT(N36,5)="JOINT",IF(MID(D36,3,6)="1007#2","15","17"),IF(RIGHT(N36,6)="SPLICE",8,IF(AND(T36="",NOT(F36="")),#REF!,T36))) -> 1.9 | K36: =IF(N36="", "", IF(OR(N36="반탈피", ISNUMBER(SEARCH("JOINT", N36))), "반", "완")) -> 완 | M36: ST731509-3T | N36: ST731454-3SS | P36: CN40 #22 | R36: MAIN PBA JOINT 2 #4 | S36: =IFERROR(VLOOKUP(M36,'DATA(STRIP LENGTH)'!A:C,3,0),"") -> 2.5 | T36: =IFERROR(VLOOKUP(N36,'DATA(STRIP LENGTH)'!A:C,3,0),"") -> 1.9 | U36: =IFERROR(VLOOKUP(M36,이원화!A:B,2,0),"") -> WB20L-61209 | V36: =IFERROR(VLOOKUP(N36,이원화!A:B,2,0),"") -> YST025L3 | W36: =IF(C36>0,IF(B36=0,W35,B36),"") -> 1767C-1
C37: 8 | D37: 1007#26/A | E37: WHT | F37: =10 + (90+20+40+50+40+90+75) +10 -> 425 | G37: 1 | H37: =IF(RIGHT(M37,5)="JOINT",IF(MID(D37,3,6)="1007#2","15","17"),IF(RIGHT(M37,6)="SPLICE",8,IF(AND(S37="",NOT(F37="")),#REF!,S37))) -> 2.5 | I37: =IF(M37="", "", IF(OR(M37="반탈피", ISNUMBER(SEARCH("JOINT", M37))), "반", "완")) -> 완 | J37: =IF(RIGHT(N37,5)="JOINT",IF(MID(D37,3,6)="1007#2","15","17"),IF(RIGHT(N37,6)="SPLICE",8,IF(AND(T37="",NOT(F37="")),#REF!,T37))) -> 1.9 | K37: =IF(N37="", "", IF(OR(N37="반탈피", ISNUMBER(SEARCH("JOINT", N37))), "반", "완")) -> 완 | M37: ST731509-3T | N37: ST731454-3SS | P37: CN40 #24 | R37: MAIN PBA JOINT 2 #6 | S37: =IFERROR(VLOOKUP(M37,'DATA(STRIP LENGTH)'!A:C,3,0),"") -> 2.5 | T37: =IFERROR(VLOOKUP(N37,'DATA(STRIP LENGTH)'!A:C,3,0),"") -> 1.9 | U37: =IFERROR(VLOOKUP(M37,이원화!A:B,2,0),"") -> WB20L-61209 | V37: =IFERROR(VLOOKUP(N37,이원화!A:B,2,0),"") -> YST025L3 | W37: =IF(C37>0,IF(B37=0,W36,B37),"") -> 1767C-1
C38: 61 | D38: 2468#26 2C (ORG/WHT) | E38: ORG | F38: =10 + (90+40+290+60) +10 -> 500 | G38: 1 | H38: =IF(RIGHT(M38,5)="JOINT",IF(MID(D38,3,6)="1007#2","15","17"),IF(RIGHT(M38,6)="SPLICE",8,IF(AND(S38="",NOT(F38="")),#REF!,S38))) -> 2.5 | I38: =IF(M38="", "", IF(OR(M38="반탈피", ISNUMBER(SEARCH("JOINT", M38))), "반", "완")) -> 완 | J38: =IF(RIGHT(N38,5)="JOINT",IF(MID(D38,3,6)="1007#2","15","17"),IF(RIGHT(N38,6)="SPLICE",8,IF(AND(T38="",NOT(F38="")),#REF!,T38))) -> 2.2 | K38: =IF(N38="", "", IF(OR(N38="반탈피", ISNUMBER(SEARCH("JOINT", N38))), "반", "완")) -> 완 | M38: ST731509-3T | N38: SXA-001T-P0.6L | P38: CN40 #15 | Q38: 4 | R38: ASSY 제빙기 JOINT #2 | S38: =IFERROR(VLOOKUP(M38,'DATA(STRIP LENGTH)'!A:C,3,0),"") -> 2.5 | T38: =IFERROR(VLOOKUP(N38,'DATA(STRIP LENGTH)'!A:C,3,0),"") -> 2.2 | U38: =IFERROR(VLOOKUP(M38,이원화!A:B,2,0),"") -> WB20L-61209 | V38: =IFERROR(VLOOKUP(N38,이원화!A:B,2,0),"") | W38: =IF(C38>0,IF(B38=0,#REF!,B38),"") -> #REF!
C39: 62 | E39: WHT | G39: 1 | H39: =IF(RIGHT(M39,5)="JOINT",IF(MID(D39,3,6)="1007#2","15","17"),IF(RIGHT(M39,6)="SPLICE",8,IF(AND(S39="",NOT(F39="")),#REF!,S39))) -> 2.5 | I39: =IF(M39="", "", IF(OR(M39="반탈피", ISNUMBER(SEARCH("JOINT", M39))), "반", "완")) -> 완 | J39: =IF(RIGHT(N39,5)="JOINT",IF(MID(D39,3,6)="1007#2","15","17"),IF(RIGHT(N39,6)="SPLICE",8,IF(AND(T39="",NOT(F39="")),#REF!,T39))) -> 2.2 | K39: =IF(N39="", "", IF(OR(N39="반탈피", ISNUMBER(SEARCH("JOINT", N39))), "반", "완")) -> 완 | M39: ST731509-3T | N39: SXA-001T-P0.6L | P39: CN40 #17 | R39: ASSY 제빙기 JOINT #1 | S39: =IFERROR(VLOOKUP(M39,'DATA(STRIP LENGTH)'!A:C,3,0),"") -> 2.5 | T39: =IFERROR(VLOOKUP(N39,'DATA(STRIP LENGTH)'!A:C,3,0),"") -> 2.2 | U39: =IFERROR(VLOOKUP(M39,이원화!A:B,2,0),"") -> WB20L-61209 | V39: =IFERROR(VLOOKUP(N39,이원화!A:B,2,0),"") | W39: =IF(C39>0,IF(B39=0,W38,B39),"") -> #REF!
C40: 68 | D40: 1007#26/A | E40: W/RED | F40: =10 + (90+40+290+60) +10 -> 500 | G40: 1 | H40: =IF(RIGHT(M40,5)="JOINT",IF(MID(D40,3,6)="1007#2","15","17"),IF(RIGHT(M40,6)="SPLICE",8,IF(AND(S40="",NOT(F40="")),#REF!,S40))) -> 2.5 | I40: =IF(M40="", "", IF(OR(M40="반탈피", ISNUMBER(SEARCH("JOINT", M40))), "반", "완")) -> 완 | J40: =IF(RIGHT(N40,5)="JOINT",IF(MID(D40,3,6)="1007#2","15","17"),IF(RIGHT(N40,6)="SPLICE",8,IF(AND(T40="",NOT(F40="")),#REF!,T40))) -> 2.2 | K40: =IF(N40="", "", IF(OR(N40="반탈피", ISNUMBER(SEARCH("JOINT", N40))), "반", "완")) -> 완 | M40: ST731509-3T | N40: SXA-001T-P0.6L | P40: CN40 #27 | R40: ASSY 제빙기 JOINT #3 | S40: =IFERROR(VLOOKUP(M40,'DATA(STRIP LENGTH)'!A:C,3,0),"") -> 2.5 | T40: =IFERROR(VLOOKUP(N40,'DATA(STRIP LENGTH)'!A:C,3,0),"") -> 2.2 | U40: =IFERROR(VLOOKUP(M40,이원화!A:B,2,0),"") -> WB20L-61209 | V40: =IFERROR(VLOOKUP(N40,이원화!A:B,2,0),"") | W40: =IF(C40>0,IF(B40=0,W39,B40),"") -> #REF!
C41: 56 | D41: 2468#26 3C (BLK/WHT) | E41: BLK | F41: =10 + (90+40+290+40) +10 -> 480 | G41: 1 | H41: =IF(RIGHT(M41,5)="JOINT",IF(MID(D41,3,6)="1007#2","15","17"),IF(RIGHT(M41,6)="SPLICE",8,IF(AND(S41="",NOT(F41="")),#REF!,S41))) -> 2.5 | I41: =IF(M41="", "", IF(OR(M41="반탈피", ISNUMBER(SEARCH("JOINT", M41))), "반", "완")) -> 완 | J41: =IF(RIGHT(N41,5)="JOINT",IF(MID(D41,3,6)="1007#2","15","17"),IF(RIGHT(N41,6)="SPLICE",8,IF(AND(T41="",NOT(F41="")),#REF!,T41))) -> 3 | K41: =IF(N41="", "", IF(OR(N41="반탈피", ISNUMBER(SEARCH("JOINT", N41))), "반", "완")) -> 완 | M41: ST731509-3T | N41: ST741461-3T | P41: CN40 #9 | Q41: 6 | R41: 디스펜서 JOINT #1 | S41: =IFERROR(VLOOKUP(M41,'DATA(STRIP LENGTH)'!A:C,3,0),"") -> 2.5 | T41: =IFERROR(VLOOKUP(N41,'DATA(STRIP LENGTH)'!A:C,3,0),"") -> 3 | U41: =IFERROR(VLOOKUP(M41,이원화!A:B,2,0),"") -> WB20L-61209 | V41: =IFERROR(VLOOKUP(N41,이원화!A:B,2,0),"") -> 25045TP | W41: =IF(C41>0,IF(B41=0,W39,B41),"") -> #REF!
C42: 57 | E42: WHT | G42: 1 | H42: =IF(RIGHT(M42,5)="JOINT",IF(MID(D42,3,6)="1007#2","15","17"),IF(RIGHT(M42,6)="SPLICE",8,IF(AND(S42="",NOT(F42="")),#REF!,S42))) -> 2.5 | I42: =IF(M42="", "", IF(OR(M42="반탈피", ISNUMBER(SEARCH("JOINT", M42))), "반", "완")) -> 완 | J42: =IF(RIGHT(N42,5)="JOINT",IF(MID(D42,3,6)="1007#2","15","17"),IF(RIGHT(N42,6)="SPLICE",8,IF(AND(T42="",NOT(F42="")),#REF!,T42))) -> 3 | K42: =IF(N42="", "", IF(OR(N42="반탈피", ISNUMBER(SEARCH("JOINT", N42))), "반", "완")) -> 완 | M42: ST731509-3T | N42: ST741461-3T | P42: CN40 #11 | R42: 디스펜서 JOINT #2 | S42: =IFERROR(VLOOKUP(M42,'DATA(STRIP LENGTH)'!A:C,3,0),"") -> 2.5 | T42: =IFERROR(VLOOKUP(N42,'DATA(STRIP LENGTH)'!A:C,3,0),"") -> 3 | U42: =IFERROR(VLOOKUP(M42,이원화!A:B,2,0),"") -> WB20L-61209 | V42: =IFERROR(VLOOKUP(N42,이원화!A:B,2,0),"") -> 25045TP | W42: =IF(C42>0,IF(B42=0,W41,B42),"") -> #REF!
C43: 58 | E43: WHT | G43: 1 | H43: =IF(RIGHT(M43,5)="JOINT",IF(MID(D43,3,6)="1007#2","15","17"),IF(RIGHT(M43,6)="SPLICE",8,IF(AND(S43="",NOT(F43="")),#REF!,S43))) -> 2.5 | I43: =IF(M43="", "", IF(OR(M43="반탈피", ISNUMBER(SEARCH("JOINT", M43))), "반", "완")) -> 완 | J43: =IF(RIGHT(N43,5)="JOINT",IF(MID(D43,3,6)="1007#2","15","17"),IF(RIGHT(N43,6)="SPLICE",8,IF(AND(T43="",NOT(F43="")),#REF!,T43))) -> 3 | K43: =IF(N43="", "", IF(OR(N43="반탈피", ISNUMBER(SEARCH("JOINT", N43))), "반", "완")) -> 완 | M43: ST731509-3T | N43: ST741461-3T | P43: CN40 #13 | R43: 디스펜서 JOINT #3 | S43: =IFERROR(VLOOKUP(M43,'DATA(STRIP LENGTH)'!A:C,3,0),"") -> 2.5 | T43: =IFERROR(VLOOKUP(N43,'DATA(STRIP LENGTH)'!A:C,3,0),"") -> 3 | U43: =IFERROR(VLOOKUP(M43,이원화!A:B,2,0),"") -> WB20L-61209 | V43: =IFERROR(VLOOKUP(N43,이원화!A:B,2,0),"") -> 25045TP | W43: =IF(C43>0,IF(B43=0,W42,B43),"") -> #REF!
G44: 1 | H44: =IF(RIGHT(M44,5)="JOINT",IF(MID(D44,3,6)="1007#2","15","17"),IF(RIGHT(M44,6)="SPLICE",8,IF(AND(S44="",NOT(F44="")),#REF!,S44))) | I44: =IF(M44="", "", IF(OR(M44="반탈피", ISNUMBER(SEARCH("JOINT", M44))), "반", "완")) | J44: =IF(RIGHT(N44,5)="JOINT",IF(MID(D44,3,6)="1007#2","15","17"),IF(RIGHT(N44,6)="SPLICE",8,IF(AND(T44="",NOT(F44="")),#REF!,T44))) | K44: =IF(N44="", "", IF(OR(N44="반탈피", ISNUMBER(SEARCH("JOINT", N44))), "반", "완")) | S44: =IFERROR(VLOOKUP(M44,'DATA(STRIP LENGTH)'!A:C,3,0),"") | T44: =IFERROR(VLOOKUP(N44,'DATA(STRIP LENGTH)'!A:C,3,0),"") | U44: =IFERROR(VLOOKUP(M44,이원화!A:B,2,0),"") | V44: =IFERROR(VLOOKUP(N44,이원화!A:B,2,0),"") | W44: =IF(C44>0,IF(B44=0,W31,B44),"")
B45: 1767C-2 | C45: 20 | D45: 2468#26 5C (ORG/WHT) | E45: ORG | F45: =10 + (80+40+50+40+40+100) +10 -> 370 | G45: 1 | H45: =IF(RIGHT(M45,5)="JOINT",IF(MID(D45,3,6)="1007#2","15","17"),IF(RIGHT(M45,6)="SPLICE",8,IF(AND(S45="",NOT(F45="")),#REF!,S45))) -> 2.5 | I45: =IF(M45="", "", IF(OR(M45="반탈피", ISNUMBER(SEARCH("JOINT", M45))), "반", "완")) -> 완 | J45: =IF(RIGHT(N45,5)="JOINT",IF(MID(D45,3,6)="1007#2","15","17"),IF(RIGHT(N45,6)="SPLICE",8,IF(AND(T45="",NOT(F45="")),#REF!,T45))) -> 3 | K45: =IF(N45="", "", IF(OR(N45="반탈피", ISNUMBER(SEARCH("JOINT", N45))), "반", "완")) -> 완 | M45: ST731509-3T | N45: ST741461-3T | O45: 1 | P45: CN50 #1 | Q45: 5 | R45: STEP VALVE JOINT #1 | S45: =IFERROR(VLOOKUP(M45,'DATA(STRIP LENGTH)'!A:C,3,0),"") -> 2.5 | T45: =IFERROR(VLOOKUP(N45,'DATA(STRIP LENGTH)'!A:C,3,0),"") -> 3 | U45: =IFERROR(VLOOKUP(M45,이원화!A:B,2,0),"") -> WB20L-61209 | V45: =IFERROR(VLOOKUP(N45,이원화!A:B,2,0),"") -> 25045TP | W45: =IF(C45>0,IF(B45=0,W44,B45),"") -> 1767C-2
C46: 21 | E46: WHT | G46: 1 | H46: =IF(RIGHT(M46,5)="JOINT",IF(MID(D46,3,6)="1007#2","15","17"),IF(RIGHT(M46,6)="SPLICE",8,IF(AND(S46="",NOT(F46="")),#REF!,S46))) -> 2.5 | I46: =IF(M46="", "", IF(OR(M46="반탈피", ISNUMBER(SEARCH("JOINT", M46))), "반", "완")) -> 완 | J46: =IF(RIGHT(N46,5)="JOINT",IF(MID(D46,3,6)="1007#2","15","17"),IF(RIGHT(N46,6)="SPLICE",8,IF(AND(T46="",NOT(F46="")),#REF!,T46))) -> 3 | K46: =IF(N46="", "", IF(OR(N46="반탈피", ISNUMBER(SEARCH("JOINT", N46))), "반", "완")) -> 완 | M46: ST731509-3T | N46: ST741461-3T | P46: CN50 #3 | R46: STEP VALVE JOINT #2 | S46: =IFERROR(VLOOKUP(M46,'DATA(STRIP LENGTH)'!A:C,3,0),"") -> 2.5 | T46: =IFERROR(VLOOKUP(N46,'DATA(STRIP LENGTH)'!A:C,3,0),"") -> 3 | U46: =IFERROR(VLOOKUP(M46,이원화!A:B,2,0),"") -> WB20L-61209 | V46: =IFERROR(VLOOKUP(N46,이원화!A:B,2,0),"") -> 25045TP | W46: =IF(C46>0,IF(B46=0,W45,B46),"") -> 1767C-2
C47: 22 | E47: WHT | G47: 1 | H47: =IF(RIGHT(M47,5)="JOINT",IF(MID(D47,3,6)="1007#2","15","17"),IF(RIGHT(M47,6)="SPLICE",8,IF(AND(S47="",NOT(F47="")),#REF!,S47))) -> 2.5 | I47: =IF(M47="", "", IF(OR(M47="반탈피", ISNUMBER(SEARCH("JOINT", M47))), "반", "완")) -> 완 | J47: =IF(RIGHT(N47,5)="JOINT",IF(MID(D47,3,6)="1007#2","15","17"),IF(RIGHT(N47,6)="SPLICE",8,IF(AND(T47="",NOT(F47="")),#REF!,T47))) -> 3 | K47: =IF(N47="", "", IF(OR(N47="반탈피", ISNUMBER(SEARCH("JOINT", N47))), "반", "완")) -> 완 | M47: ST731509-3T | N47: ST741461-3T | P47: CN50 #5 | R47: STEP VALVE JOINT #3 | S47: =IFERROR(VLOOKUP(M47,'DATA(STRIP LENGTH)'!A:C,3,0),"") -> 2.5 | T47: =IFERROR(VLOOKUP(N47,'DATA(STRIP LENGTH)'!A:C,3,0),"") -> 3 | U47: =IFERROR(VLOOKUP(M47,이원화!A:B,2,0),"") -> WB20L-61209 | V47: =IFERROR(VLOOKUP(N47,이원화!A:B,2,0),"") -> 25045TP | W47: =IF(C47>0,IF(B47=0,W46,B47),"") -> 1767C-2
C48: 23 | E48: WHT | G48: 1 | H48: =IF(RIGHT(M48,5)="JOINT",IF(MID(D48,3,6)="1007#2","15","17"),IF(RIGHT(M48,6)="SPLICE",8,IF(AND(S48="",NOT(F48="")),#REF!,S48))) -> 2.5 | I48: =IF(M48="", "", IF(OR(M48="반탈피", ISNUMBER(SEARCH("JOINT", M48))), "반", "완")) -> 완 | J48: =IF(RIGHT(N48,5)="JOINT",IF(MID(D48,3,6)="1007#2","15","17"),IF(RIGHT(N48,6)="SPLICE",8,IF(AND(T48="",NOT(F48="")),#REF!,T48))) -> 3 | K48: =IF(N48="", "", IF(OR(N48="반탈피", ISNUMBER(SEARCH("JOINT", N48))), "반", "완")) -> 완 | M48: ST731509-3T | N48: ST741461-3T | P48: CN50 #7 | R48: STEP VALVE JOINT #4 | S48: =IFERROR(VLOOKUP(M48,'DATA(STRIP LENGTH)'!A:C,3,0),"") -> 2.5 | T48: =IFERROR(VLOOKUP(N48,'DATA(STRIP LENGTH)'!A:C,3,0),"") -> 3 | U48: =IFERROR(VLOOKUP(M48,이원화!A:B,2,0),"") -> WB20L-61209 | V48: =IFERROR(VLOOKUP(N48,이원화!A:B,2,0),"") -> 25045TP | W48: =IF(C48>0,IF(B48=0,W47,B48),"") -> 1767C-2
C49: 24 | E49: WHT | G49: 1 | H49: =IF(RIGHT(M49,5)="JOINT",IF(MID(D49,3,6)="1007#2","15","17"),IF(RIGHT(M49,6)="SPLICE",8,IF(AND(S49="",NOT(F49="")),#REF!,S49))) -> 2.5 | I49: =IF(M49="", "", IF(OR(M49="반탈피", ISNUMBER(SEARCH("JOINT", M49))), "반", "완")) -> 완 | J49: =IF(RIGHT(N49,5)="JOINT",IF(MID(D49,3,6)="1007#2","15","17"),IF(RIGHT(N49,6)="SPLICE",8,IF(AND(T49="",NOT(F49="")),#REF!,T49))) -> 3 | K49: =IF(N49="", "", IF(OR(N49="반탈피", ISNUMBER(SEARCH("JOINT", N49))), "반", "완")) -> 완 | M49: ST731509-3T | N49: ST741461-3T | P49: CN50 #9 | R49: STEP VALVE JOINT #5 | S49: =IFERROR(VLOOKUP(M49,'DATA(STRIP LENGTH)'!A:C,3,0),"") -> 2.5 | T49: =IFERROR(VLOOKUP(N49,'DATA(STRIP LENGTH)'!A:C,3,0),"") -> 3 | U49: =IFERROR(VLOOKUP(M49,이원화!A:B,2,0),"") -> WB20L-61209 | V49: =IFERROR(VLOOKUP(N49,이원화!A:B,2,0),"") -> 25045TP | W49: =IF(C49>0,IF(B49=0,W48,B49),"") -> 1767C-2
...

Sheet PT
A1: `
A3: NO | B3: 품 명 | C3: 자코드 | D3: 규 격 | E3: 단위 | F3: 소요량 | G3: 요청수량 | H3: 분류 | I3: 적용코드 | J3: 품명 | K3: 자코드 | L3: 이원화 자재
A4: =ROW(A4)-3 -> 1 | B4: =J4 -> HOUSING | C4: =K4 -> HOU1810 | D4: MG615674-026 | E4: EA | F4: 1 | H4: 2 | I4: 1767C-1 | J4: =VLOOKUP(D4,[1]자코드!$F:$H,2,0) -> HOUSING | K4: =VLOOKUP(D4,[1]자코드!$F:$H,3,0) -> HOU1810 | L4: =IFERROR(VLOOKUP(D4,[2]이원화!A:B,2,0),"") -> WB20M-026-411
A5: =ROW(A5)-3 -> 2 | B5: =J5 -> TPA | C5: =K5 -> TPA0341 | D5: MG635939-213 | E5: EA | F5: 2 | I5: 1767C-1 | J5: =VLOOKUP(D5,[1]자코드!$F:$H,2,0) -> TPA | K5: =VLOOKUP(D5,[1]자코드!$F:$H,3,0) -> TPA0341 | L5: =IFERROR(VLOOKUP(D5,[2]이원화!A:B,2,0),"") -> WB20M-026-454
A6: =ROW(A6)-3 -> 3 | B6: =J6 -> HOUSING | C6: =K6 -> HOU1790 | D6: MG615632-012 | E6: EA | F6: 1 | H6: 8 | I6: 1767C-1 | J6: =VLOOKUP(D6,[1]자코드!$F:$H,2,0) -> HOUSING | K6: =VLOOKUP(D6,[1]자코드!$F:$H,3,0) -> HOU1790 | L6: =IFERROR(VLOOKUP(D6,[2]이원화!A:B,2,0),"") -> SMH250-12LZ
A7: =ROW(A7)-3 -> 4 | B7: =J7 -> TPA | C7: =K7 -> TPA0335 | D7: MG635826-212 | E7: EA | F7: 1 | I7: 1767C-1 | J7: =VLOOKUP(D7,[1]자코드!$F:$H,2,0) -> TPA | K7: =VLOOKUP(D7,[1]자코드!$F:$H,3,0) -> TPA0335 | L7: =IFERROR(VLOOKUP(D7,[2]이원화!A:B,2,0),"") -> SMH250J-12RT(RE)
A8: =ROW(A8)-3 -> 5 | B8: =J8 -> HOUSING | C8: =K8 -> HOU1788 | D8: MG615632-010 | E8: EA | F8: 1 | H8: 7 | I8: 1767C-1 | J8: =VLOOKUP(D8,[1]자코드!$F:$H,2,0) -> HOUSING | K8: =VLOOKUP(D8,[1]자코드!$F:$H,3,0) -> HOU1788 | L8: =IFERROR(VLOOKUP(D8,[2]이원화!A:B,2,0),"") -> SMH250-10LZ
A9: =ROW(A9)-3 -> 6 | B9: =J9 -> TPA | C9: =K9 -> TPA0333 | D9: MG635826-210 | E9: EA | F9: 1 | I9: 1767C-1 | J9: =VLOOKUP(D9,[1]자코드!$F:$H,2,0) -> TPA | K9: =VLOOKUP(D9,[1]자코드!$F:$H,3,0) -> TPA0333 | L9: =IFERROR(VLOOKUP(D9,[2]이원화!A:B,2,0),"") -> SMH250J-10RT(RE)
A11: =ROW(A11)-3 -> 8 | B11: =J11 -> HOUSING | C11: =K11 -> HOU1809 | D11: MG615674-028 | E11: EA | F11: 1 | H11: 1 | I11: 1767C-2 | J11: =VLOOKUP(D11,[1]자코드!$F:$H,2,0) -> HOUSING | K11: =VLOOKUP(D11,[1]자코드!$F:$H,3,0) -> HOU1809 | L11: =IFERROR(VLOOKUP(D11,[2]이원화!A:B,2,0),"") -> WB20M-028-411
A12: =ROW(A12)-3 -> 9 | B12: =J12 -> TPA | C12: =K12 -> TPA0340 | D12: MG635939-214 | E12: EA | F12: 2 | I12: 1767C-2 | J12: =VLOOKUP(D12,[1]자코드!$F:$H,2,0) -> TPA | K12: =VLOOKUP(D12,[1]자코드!$F:$H,3,0) -> TPA0340 | L12: =IFERROR(VLOOKUP(D12,[2]이원화!A:B,2,0),"") -> WB20M-028-454
A13: =ROW(A13)-3 -> 10 | B13: HOUSING | C13: HOU2507 | D13: XMP-18VC-WGL1 | E13: EA | F13: 1 | H13: 4 | I13: 1767C-2 | J13: =VLOOKUP(D13,[1]자코드!$F:$H,2,0) -> #N/A | K13: =VLOOKUP(D13,[1]자코드!$F:$H,3,0) -> #N/A | L13: =IFERROR(VLOOKUP(D13,[2]이원화!A:B,2,0),"")
A14: =ROW(A14)-3 -> 11 | B14: =J14 -> TPA | C14: =K14 -> TPA0161 | D14: X2.5-09 | E14: EA | F14: 2 | I14: 1767C-2 | J14: =VLOOKUP(D14,[1]자코드!$F:$H,2,0) -> TPA | K14: =VLOOKUP(D14,[1]자코드!$F:$H,3,0) -> TPA0161 | L14: =IFERROR(VLOOKUP(D14,[2]이원화!A:B,2,0),"")
A15: =ROW(A15)-3 -> 12 | B15: HOUSING | C15: HOU2532 | D15: MG625500-012 | E15: EA | F15: 1 | H15: 5 | I15: 1767C-2 | J15: =VLOOKUP(D15,[1]자코드!$F:$H,2,0) -> #N/A | K15: =VLOOKUP(D15,[1]자코드!$F:$H,3,0) -> #N/A | L15: =IFERROR(VLOOKUP(D15,[2]이원화!A:B,2,0),"") -> 25045HP-12AZ
A16: =ROW(A16)-3 -> 13 | B16: =J16 -> TPA | C16: =K16 -> TPA0335 | D16: MG635826-212 | E16: EA | F16: 1 | I16: 1767C-2 | J16: =VLOOKUP(D16,[1]자코드!$F:$H,2,0) -> TPA | K16: =VLOOKUP(D16,[1]자코드!$F:$H,3,0) -> TPA0335 | L16: =IFERROR(VLOOKUP(D16,[2]이원화!A:B,2,0),"") -> SMH250J-12RT(RE)
A17: =ROW(A17)-3 -> 14 | B17: =J17 -> HOUSING | C17: =K17 -> HOU2422 | D17: MG625500-007 | E17: EA | F17: 1 | H17: 6 | I17: 1767C-2 | J17: =VLOOKUP(D17,[1]자코드!$F:$H,2,0) -> HOUSING | K17: =VLOOKUP(D17,[1]자코드!$F:$H,3,0) -> HOU2422 | L17: =IFERROR(VLOOKUP(D17,[2]이원화!A:B,2,0),"") -> 25045HP-07AZ
A18: =ROW(A18)-3 -> 15 | B18: =J18 -> TPA | C18: =K18 -> TPA0330 | D18: MG635826-207 | E18: EA | F18: 1 | I18: 1767C-2 | J18: =VLOOKUP(D18,[1]자코드!$F:$H,2,0) -> TPA | K18: =VLOOKUP(D18,[1]자코드!$F:$H,3,0) -> TPA0330 | L18: =IFERROR(VLOOKUP(D18,[2]이원화!A:B,2,0),"") -> SMH250J-07RT(RE)
A20: =ROW(A20)-3 -> 17 | B20: =J20 -> HOUSING | C20: =K20 -> HOU1859 | D20: MG615674-024 | E20: EA | F20: 1 | H20: 3 | I20: 1767C-3 | J20: =VLOOKUP(D20,[1]자코드!$F:$H,2,0) -> HOUSING | K20: =VLOOKUP(D20,[1]자코드!$F:$H,3,0) -> HOU1859 | L20: =IFERROR(VLOOKUP(D20,[2]이원화!A:B,2,0),"") -> WB20M-024-411
A21: =ROW(A21)-3 -> 18 | B21: =J21 -> TPA | C21: =K21 -> TPA0348 | D21: MG635939-212 | E21: EA | F21: 2 | I21: 1767C-3 | J21: =VLOOKUP(D21,[1]자코드!$F:$H,2,0) -> TPA | K21: =VLOOKUP(D21,[1]자코드!$F:$H,3,0) -> TPA0348 | L21: =IFERROR(VLOOKUP(D21,[2]이원화!A:B,2,0),"") -> WB20M-024-454
J22: =VLOOKUP(D22,[1]자코드!$F:$H,2,0) -> #N/A | K22: =VLOOKUP(D22,[1]자코드!$F:$H,3,0) -> #N/A | L22: =IFERROR(VLOOKUP(D22,[2]이원화!A:B,2,0),"")
A23: =ROW(A23)-3 -> 20 | B23: =J23 -> PVC TAPE | C23: =K23 -> TAP0035 | D23: 19M/MX20 (WHT) | E23: M | F23: 2.3 | I23: DA96-01767C | J23: =VLOOKUP(D23,[1]자코드!$F:$H,2,0) -> PVC TAPE | K23: =VLOOKUP(D23,[1]자코드!$F:$H,3,0) -> TAP0035 | L23: =IFERROR(VLOOKUP(D23,[2]이원화!A:B,2,0),"")
A24: =ROW(A24)-3 -> 21 | B24: =J24 -> LABEL | C24: =K24 -> LAB1197 | D24: LABEL 20X15 | E24: EA | F24: 1 | I24: DA96-01767C | J24: =VLOOKUP(D24,[1]자코드!$F:$H,2,0) -> LABEL | K24: =VLOOKUP(D24,[1]자코드!$F:$H,3,0) -> LAB1197 | L24: =IFERROR(VLOOKUP(D24,[2]이원화!A:B,2,0),"")
A25: =ROW(A25)-3 -> 22 | B25: FIXER COVER | C25: INJ0559 | D25: DA61-16643A | E25: EA | F25: 1 | I25: DA96-01767C | J25: =VLOOKUP(D25,[1]자코드!$F:$H,2,0) -> #N/A | K25: =VLOOKUP(D25,[1]자코드!$F:$H,3,0) -> #N/A | L25: =IFERROR(VLOOKUP(D25,[2]이원화!A:B,2,0),"")
A26: =ROW(A26)-3 -> 23 | B26: =J26 -> PVC TUBE | C26: =K26 -> TUB0102 | D26: UL9.5Ø0.5T/BLKGARUM#3/8(10Ø) | E26: M | F26: 0.07 | I26: DA96-01767C | J26: =VLOOKUP(D26,[1]자코드!$F:$H,2,0) -> PVC TUBE | K26: =VLOOKUP(D26,[1]자코드!$F:$H,3,0) -> TUB0102 | L26: =IFERROR(VLOOKUP(D26,[2]이원화!A:B,2,0),"")
A27: =ROW(A27)-3 -> 24 | B27: =J27 -> #N/A | C27: =K27 -> #N/A | I27: DA96-01767C | J27: =VLOOKUP(D27,[1]자코드!$F:$H,2,0) -> #N/A | K27: =VLOOKUP(D27,[1]자코드!$F:$H,3,0) -> #N/A | L27: =IFERROR(VLOOKUP(D27,[2]이원화!A:B,2,0),"")
A28: =ROW(A28)-3 -> 25 | B28: =J28 -> #N/A | C28: =K28 -> #N/A | J28: =VLOOKUP(D28,[1]자코드!$F:$H,2,0) -> #N/A | K28: =VLOOKUP(D28,[1]자코드!$F:$H,3,0) -> #N/A | L28: =IFERROR(VLOOKUP(D28,[2]이원화!A:B,2,0),"")
A29: =ROW(A29)-3 -> 26 | B29: =J29 -> #N/A | C29: =K29 -> #N/A | J29: =VLOOKUP(D29,[1]자코드!$F:$H,2,0) -> #N/A | K29: =VLOOKUP(D29,[1]자코드!$F:$H,3,0) -> #N/A | L29: =IFERROR(VLOOKUP(D29,[2]이원화!A:B,2,0),"")
A30: =ROW(A30)-3 -> 27 | B30: =J30 -> #N/A | C30: =K30 -> #N/A | J30: =VLOOKUP(D30,[1]자코드!$F:$H,2,0) -> #N/A | K30: =VLOOKUP(D30,[1]자코드!$F:$H,3,0) -> #N/A | L30: =IFERROR(VLOOKUP(D30,[2]이원화!A:B,2,0),"")
A31: =ROW(A31)-3 -> 28 | B31: =J31 -> #N/A | C31: =K31 -> #N/A | J31: =VLOOKUP(D31,[1]자코드!$F:$H,2,0) -> #N/A | K31: =VLOOKUP(D31,[1]자코드!$F:$H,3,0) -> #N/A | L31: =IFERROR(VLOOKUP(D31,[2]이원화!A:B,2,0),"")
A32: =ROW(A32)-3 -> 29 | B32: =J32 -> #N/A | C32: =K32 -> #N/A | J32: =VLOOKUP(D32,[1]자코드!$F:$H,2,0) -> #N/A | K32: =VLOOKUP(D32,[1]자코드!$F:$H,3,0) -> #N/A | L32: =IFERROR(VLOOKUP(D32,[2]이원화!A:B,2,0),"")
A33: =ROW(A33)-3 -> 30 | B33: =J33 -> #N/A | C33: =K33 -> #N/A | J33: =VLOOKUP(D33,[1]자코드!$F:$H,2,0) -> #N/A | K33: =VLOOKUP(D33,[1]자코드!$F:$H,3,0) -> #N/A | L33: =IFERROR(VLOOKUP(D33,[2]이원화!A:B,2,0),"")
A34: =ROW(A34)-3 -> 31 | B34: =J34 -> #N/A | C34: =K34 -> #N/A | J34: =VLOOKUP(D34,[1]자코드!$F:$H,2,0) -> #N/A | K34: =VLOOKUP(D34,[1]자코드!$F:$H,3,0) -> #N/A | L34: =IFERROR(VLOOKUP(D34,[2]이원화!A:B,2,0),"")
A35: =ROW(A35)-3 -> 32 | B35: =J35 -> #N/A | C35: =K35 -> #N/A | J35: =VLOOKUP(D35,[1]자코드!$F:$H,2,0) -> #N/A | K35: =VLOOKUP(D35,[1]자코드!$F:$H,3,0) -> #N/A | L35: =IFERROR(VLOOKUP(D35,[2]이원화!A:B,2,0),"")
A36: =ROW(A36)-3 -> 33 | B36: =J36 -> #N/A | C36: =K36 -> #N/A | J36: =VLOOKUP(D36,[1]자코드!$F:$H,2,0) -> #N/A | K36: =VLOOKUP(D36,[1]자코드!$F:$H,3,0) -> #N/A | L36: =IFERROR(VLOOKUP(D36,[2]이원화!A:B,2,0),"")
A37: =ROW(A37)-3 -> 34 | B37: =J37 -> #N/A | C37: =K37 -> #N/A | J37: =VLOOKUP(D37,[1]자코드!$F:$H,2,0) -> #N/A | K37: =VLOOKUP(D37,[1]자코드!$F:$H,3,0) -> #N/A | L37: =IFERROR(VLOOKUP(D37,[2]이원화!A:B,2,0),"")
A38: =ROW(A38)-3 -> 35 | B38: =J38 -> #N/A | C38: =K38 -> #N/A | J38: =VLOOKUP(D38,[1]자코드!$F:$H,2,0) -> #N/A | K38: =VLOOKUP(D38,[1]자코드!$F:$H,3,0) -> #N/A | L38: =IFERROR(VLOOKUP(D38,[2]이원화!A:B,2,0),"")
A39: =ROW(A39)-3 -> 36 | B39: =J39 -> #N/A | C39: =K39 -> #N/A | J39: =VLOOKUP(D39,[1]자코드!$F:$H,2,0) -> #N/A | K39: =VLOOKUP(D39,[1]자코드!$F:$H,3,0) -> #N/A | L39: =IFERROR(VLOOKUP(D39,[2]이원화!A:B,2,0),"")
... A88: =ROW(A88)-3 -> 85 | B88: =J88 -> #N/A | C88: =K88 -> #N/A | J88: =VLOOKUP(D88,[1]자코드!$F:$H,2,0) -> #N/A | K88: =VLOOKUP(D88,[1]자코드!$F:$H,3,0) -> #N/A | L88: =IFERROR(VLOOKUP(D88,[2]이원화!A:B,2,0),"")

Sheet DATA(STRIP LENGTH)
A2: Terminal | B2: Strip Length (커넥터 제조사 규격) | C2: SELIM
A3: SXA-001T-P0.6 | B3: 2.2 | C3: 2.2
A4: 5-170063-2 | B4: 4.75 | C4: 4.75
A5: ST731594-3T | B5: 1.3~1.6 | C5: 1.5
A6: 20003TS | B6: 1.5~2 | C6: 1.9
A7: 반탈피 | C7: 길이 입력
A25: 20003TS(L) | B25: 1.5~2 | C25: 1.9
A26: YST200-H3 | B26: 1.5~2.0 | C26: 2
A27: ST731454-3SS | B27: 1.7~1.9 | C27: 1.9
A28: ST731509-3S | B28: 1.7~1.9 | C28: 1.9
A29: ST731509-3T | B29: 1.7~1.9 | C29: 2.5
A30: ST741476-3S | B30: 1.8~2.1 | C30: 2
A31: ST741476-3T | B31: 1.8~2.1 | C31: 2
A32: SXM-001T-P0.6 | B32: 1.9~2.4 | C32: 2
A33: YDT200 | B33: 2.0~2.5 | C33: 2
A34: YDT200-C | B34: 2.0~2.5 | C34: 2
A35: YST025L3 | B35: 2.2~2.7 | C35: 2.7
A36: ST731504-3S | B36: 2.5~2.7 | C36: 2.5
... A121: ST760320-2 | B121: 7.5~8.5 | C121: 10
A122: 0039000454(5558T2-A)
A123: 39000040(5558T)
A124: 39000038(5556T) | C124: 3.5
A125: SC41202-005A
A126: SC42205-005A | B126: 2.8 ~ 3.3 | C126: 3
A127: 25045TP | B127: 2.6~3.1 | C127: 2.7
A128: ST730571-3 | B128: 5.0~5.5 | C128: 5
A129: ST761319-3 | B129: 5.5~6.0 | C129: 5.5
A130: ST761320-3 | B130: 5.5~6.0 | C130: 5.5
A131: ST730570-3 | B131: 5.0~5.5 | C131: 5
A132: ST730571-3 | B132: 5.0~5.5 | C132: 5
A133: ST730572-3 | B133: 5.0~5.5 | C133: 5
A134: ST731342-3 | B134: 3.5~4.0 | C134: 3.5
A135: ST710237-2 | B135: 6.5~7.0 | C135: 6.5
A136: 170325-1 | B136: 4.0~5.0 | C136: 4.7
A137: 170326-1 | B137: 4.0~5.0 | C137: 5
A138: 41728 | C138: 5
A139: 63677-1 | C139: 5
A140: ST731394-3S | B140: 4.8~5.3 | C140: 5
A141: ST730268-3 | B141: 5.0~5.5 | C141: 5.5
A142: ST730206-3 | B142: 4.0~4.5 | C142: 4.5
...

Sheet 인장력
A2: WIRE SPEC | B2: 인장력
A3: UL1007#26 | B3: 2.5kgf
A4: UL1007#26/A | B4: 2.5kgf
A5: UL1007#24 | B5: 3kgf
A6: UL1007#24/A | B6: 3kgf
A7: UL1007#22 | B7: 4.5kgf
A8: UL1007#22/A | B8: 4.5kgf
A9: UL1007#20 | B9: 8kgf
A10: UL1007#20/A | B10: 8kgf
A11: UL1015#24 | B11: 3kgf
A12: UL1015#24/A | B12: 3kgf
A13: UL1015#22 | B13: 4.5kgf
... A165: 2651#26 3C (YEL/WHT) | B165: 2.5kgf

Sheet 이원화
A1: 형명 (색상별 구분 작성) | B1: 형명 (색상별 구분 작성)
A2: 35965-0200 | B2: MG615695-002
A3: 35965-0202 | B3: MG615695-102
A4: 35965-0203 | B4: MG615695-302
A5: 35965-0204 | B5: MG615695-202
A6: 35965-9200 | B6: MG615695-002
A7: 35965-9202 | B7: MG615695-102
A8: 35965-9203 | B8: MG615695-302
A9: 35965-9204 | B9: MG615695-202
A10: 35965-0210 | B10: MG615696-002
A11: 35965-0212 | B11: MG615696-102
A12: 35965-0213 | B12: MG615696-302
... A551: ST741436-3DW | B551: 35747-0310
